[2022-11-30T09:49:01.994+0000] {taskinstance.py:1165} INFO - Dependencies all met for <TaskInstance: a_start_dag.count manual__2022-11-30T09:48:58.732868+00:00 [queued]>
[2022-11-30T09:49:02.012+0000] {taskinstance.py:1165} INFO - Dependencies all met for <TaskInstance: a_start_dag.count manual__2022-11-30T09:48:58.732868+00:00 [queued]>
[2022-11-30T09:49:02.012+0000] {taskinstance.py:1362} INFO - 
--------------------------------------------------------------------------------
[2022-11-30T09:49:02.012+0000] {taskinstance.py:1363} INFO - Starting attempt 1 of 1
[2022-11-30T09:49:02.012+0000] {taskinstance.py:1364} INFO - 
--------------------------------------------------------------------------------
[2022-11-30T09:49:02.036+0000] {taskinstance.py:1383} INFO - Executing <Task(PythonOperator): count> on 2022-11-30 09:48:58.732868+00:00
[2022-11-30T09:49:02.046+0000] {standard_task_runner.py:55} INFO - Started process 3905 to run task
[2022-11-30T09:49:02.051+0000] {standard_task_runner.py:82} INFO - Running: ['***', 'tasks', 'run', 'a_start_dag', 'count', 'manual__2022-11-30T09:48:58.732868+00:00', '--job-id', '1055', '--raw', '--subdir', 'DAGS_FOLDER/start_dag.py', '--cfg-path', '/tmp/tmpqmlxmvfy']
[2022-11-30T09:49:02.052+0000] {standard_task_runner.py:83} INFO - Job 1055: Subtask count
[2022-11-30T09:49:02.113+0000] {task_command.py:376} INFO - Running <TaskInstance: a_start_dag.count manual__2022-11-30T09:48:58.732868+00:00 [running]> on host ab28c0b87467
[2022-11-30T09:49:02.182+0000] {taskinstance.py:1592} INFO - Exporting the following env vars:
AIRFLOW_CTX_DAG_OWNER=***
AIRFLOW_CTX_DAG_ID=a_start_dag
AIRFLOW_CTX_TASK_ID=count
AIRFLOW_CTX_EXECUTION_DATE=2022-11-30T09:48:58.732868+00:00
AIRFLOW_CTX_TRY_NUMBER=1
AIRFLOW_CTX_DAG_RUN_ID=manual__2022-11-30T09:48:58.732868+00:00
[2022-11-30T09:49:02.205+0000] {taskinstance.py:1851} ERROR - Task failed with exception
Traceback (most recent call last):
  File "/home/airflow/.local/lib/python3.7/site-packages/airflow/operators/python.py", line 175, in execute
    return_value = self.execute_callable()
  File "/home/airflow/.local/lib/python3.7/site-packages/airflow/operators/python.py", line 193, in execute_callable
    return self.python_callable(*self.op_args, **self.op_kwargs)
  File "/opt/airflow/dags/start_dag.py", line 16, in count_r
    item_dict = json.load(r)
  File "/usr/local/lib/python3.7/json/__init__.py", line 293, in load
    return loads(fp.read(),
AttributeError: 'str' object has no attribute 'read'
[2022-11-30T09:49:02.212+0000] {taskinstance.py:1406} INFO - Marking task as FAILED. dag_id=a_start_dag, task_id=count, execution_date=20221130T094858, start_date=20221130T094901, end_date=20221130T094902
[2022-11-30T09:49:02.224+0000] {standard_task_runner.py:105} ERROR - Failed to execute job 1055 for task count ('str' object has no attribute 'read'; 3905)
[2022-11-30T09:49:02.261+0000] {local_task_job.py:159} INFO - Task exited with return code 1
[2022-11-30T09:49:02.278+0000] {taskinstance.py:2623} INFO - 0 downstream tasks scheduled from follow-on schedule check
