[2022-11-29T11:12:49.428+0000] {taskinstance.py:1165} INFO - Dependencies all met for <TaskInstance: start_dag.world manual__2022-11-29T11:12:48.434427+00:00 [queued]>
[2022-11-29T11:12:49.440+0000] {taskinstance.py:1165} INFO - Dependencies all met for <TaskInstance: start_dag.world manual__2022-11-29T11:12:48.434427+00:00 [queued]>
[2022-11-29T11:12:49.440+0000] {taskinstance.py:1362} INFO - 
--------------------------------------------------------------------------------
[2022-11-29T11:12:49.440+0000] {taskinstance.py:1363} INFO - Starting attempt 1 of 1
[2022-11-29T11:12:49.440+0000] {taskinstance.py:1364} INFO - 
--------------------------------------------------------------------------------
[2022-11-29T11:12:49.456+0000] {taskinstance.py:1383} INFO - Executing <Task(PythonOperator): world> on 2022-11-29 11:12:48.434427+00:00
[2022-11-29T11:12:49.463+0000] {standard_task_runner.py:55} INFO - Started process 9057 to run task
[2022-11-29T11:12:49.466+0000] {standard_task_runner.py:82} INFO - Running: ['***', 'tasks', 'run', 'start_dag', 'world', 'manual__2022-11-29T11:12:48.434427+00:00', '--job-id', '658', '--raw', '--subdir', 'DAGS_FOLDER/start_dag.py', '--cfg-path', '/tmp/tmpd3btfso9']
[2022-11-29T11:12:49.466+0000] {standard_task_runner.py:83} INFO - Job 658: Subtask world
[2022-11-29T11:12:49.527+0000] {task_command.py:376} INFO - Running <TaskInstance: start_dag.world manual__2022-11-29T11:12:48.434427+00:00 [running]> on host ab28c0b87467
[2022-11-29T11:12:49.601+0000] {taskinstance.py:1592} INFO - Exporting the following env vars:
AIRFLOW_CTX_DAG_OWNER=***
AIRFLOW_CTX_DAG_ID=start_dag
AIRFLOW_CTX_TASK_ID=world
AIRFLOW_CTX_EXECUTION_DATE=2022-11-29T11:12:48.434427+00:00
AIRFLOW_CTX_TRY_NUMBER=1
AIRFLOW_CTX_DAG_RUN_ID=manual__2022-11-29T11:12:48.434427+00:00
[2022-11-29T11:12:49.601+0000] {taskinstance.py:1851} ERROR - Task failed with exception
Traceback (most recent call last):
  File "/home/airflow/.local/lib/python3.7/site-packages/airflow/operators/python.py", line 175, in execute
    return_value = self.execute_callable()
  File "/home/airflow/.local/lib/python3.7/site-packages/airflow/operators/python.py", line 193, in execute_callable
    return self.python_callable(*self.op_args, **self.op_kwargs)
  File "/opt/airflow/dags/start_dag.py", line 8, in hello
    url = Variable.get(url_csv, deserialize_json=True)
NameError: name 'url_csv' is not defined
[2022-11-29T11:12:49.609+0000] {taskinstance.py:1406} INFO - Marking task as FAILED. dag_id=start_dag, task_id=world, execution_date=20221129T111248, start_date=20221129T111249, end_date=20221129T111249
[2022-11-29T11:12:49.621+0000] {standard_task_runner.py:105} ERROR - Failed to execute job 658 for task world (name 'url_csv' is not defined; 9057)
[2022-11-29T11:12:49.639+0000] {local_task_job.py:159} INFO - Task exited with return code 1
[2022-11-29T11:12:49.656+0000] {taskinstance.py:2623} INFO - 0 downstream tasks scheduled from follow-on schedule check
