[2022-11-29T15:27:09.579+0000] {taskinstance.py:1165} INFO - Dependencies all met for <TaskInstance: a_start_dag.count_row manual__2022-11-29T15:27:08.009221+00:00 [queued]>
[2022-11-29T15:27:09.591+0000] {taskinstance.py:1165} INFO - Dependencies all met for <TaskInstance: a_start_dag.count_row manual__2022-11-29T15:27:08.009221+00:00 [queued]>
[2022-11-29T15:27:09.591+0000] {taskinstance.py:1362} INFO - 
--------------------------------------------------------------------------------
[2022-11-29T15:27:09.591+0000] {taskinstance.py:1363} INFO - Starting attempt 1 of 1
[2022-11-29T15:27:09.592+0000] {taskinstance.py:1364} INFO - 
--------------------------------------------------------------------------------
[2022-11-29T15:27:09.611+0000] {taskinstance.py:1383} INFO - Executing <Task(PythonOperator): count_row> on 2022-11-29 15:27:08.009221+00:00
[2022-11-29T15:27:09.621+0000] {standard_task_runner.py:55} INFO - Started process 20880 to run task
[2022-11-29T15:27:09.626+0000] {standard_task_runner.py:82} INFO - Running: ['***', 'tasks', 'run', 'a_start_dag', 'count_row', 'manual__2022-11-29T15:27:08.009221+00:00', '--job-id', '1011', '--raw', '--subdir', 'DAGS_FOLDER/start_dag.py', '--cfg-path', '/tmp/tmpfv_qzph3']
[2022-11-29T15:27:09.627+0000] {standard_task_runner.py:83} INFO - Job 1011: Subtask count_row
[2022-11-29T15:27:09.710+0000] {task_command.py:376} INFO - Running <TaskInstance: a_start_dag.count_row manual__2022-11-29T15:27:08.009221+00:00 [running]> on host ab28c0b87467
[2022-11-29T15:27:09.794+0000] {taskinstance.py:1592} INFO - Exporting the following env vars:
AIRFLOW_CTX_DAG_OWNER=***
AIRFLOW_CTX_DAG_ID=a_start_dag
AIRFLOW_CTX_TASK_ID=count_row
AIRFLOW_CTX_EXECUTION_DATE=2022-11-29T15:27:08.009221+00:00
AIRFLOW_CTX_TRY_NUMBER=1
AIRFLOW_CTX_DAG_RUN_ID=manual__2022-11-29T15:27:08.009221+00:00
[2022-11-29T15:27:10.489+0000] {taskinstance.py:1851} ERROR - Task failed with exception
Traceback (most recent call last):
  File "/home/airflow/.local/lib/python3.7/site-packages/airflow/operators/python.py", line 175, in execute
    return_value = self.execute_callable()
  File "/home/airflow/.local/lib/python3.7/site-packages/airflow/operators/python.py", line 193, in execute_callable
    return self.python_callable(*self.op_args, **self.op_kwargs)
  File "/opt/airflow/dags/start_dag.py", line 11, in count_r
    row_sum = r.text.count('\n')-1
  File "/home/airflow/.local/lib/python3.7/site-packages/pandas/core/generic.py", line 5487, in __getattr__
    return object.__getattribute__(self, name)
AttributeError: 'DataFrame' object has no attribute 'text'
[2022-11-29T15:27:10.499+0000] {taskinstance.py:1406} INFO - Marking task as FAILED. dag_id=a_start_dag, task_id=count_row, execution_date=20221129T152708, start_date=20221129T152709, end_date=20221129T152710
[2022-11-29T15:27:10.516+0000] {standard_task_runner.py:105} ERROR - Failed to execute job 1011 for task count_row ('DataFrame' object has no attribute 'text'; 20880)
[2022-11-29T15:27:10.529+0000] {local_task_job.py:159} INFO - Task exited with return code 1
[2022-11-29T15:27:10.549+0000] {taskinstance.py:2623} INFO - 0 downstream tasks scheduled from follow-on schedule check
