[2022-11-29T15:52:25.102+0000] {taskinstance.py:1165} INFO - Dependencies all met for <TaskInstance: a_start_dag.count_row manual__2022-11-29T15:52:24.001658+00:00 [queued]>
[2022-11-29T15:52:25.114+0000] {taskinstance.py:1165} INFO - Dependencies all met for <TaskInstance: a_start_dag.count_row manual__2022-11-29T15:52:24.001658+00:00 [queued]>
[2022-11-29T15:52:25.114+0000] {taskinstance.py:1362} INFO - 
--------------------------------------------------------------------------------
[2022-11-29T15:52:25.114+0000] {taskinstance.py:1363} INFO - Starting attempt 1 of 1
[2022-11-29T15:52:25.115+0000] {taskinstance.py:1364} INFO - 
--------------------------------------------------------------------------------
[2022-11-29T15:52:25.133+0000] {taskinstance.py:1383} INFO - Executing <Task(PythonOperator): count_row> on 2022-11-29 15:52:24.001658+00:00
[2022-11-29T15:52:25.141+0000] {standard_task_runner.py:55} INFO - Started process 21980 to run task
[2022-11-29T15:52:25.144+0000] {standard_task_runner.py:82} INFO - Running: ['***', 'tasks', 'run', 'a_start_dag', 'count_row', 'manual__2022-11-29T15:52:24.001658+00:00', '--job-id', '1012', '--raw', '--subdir', 'DAGS_FOLDER/start_dag.py', '--cfg-path', '/tmp/tmpopmrti4x']
[2022-11-29T15:52:25.146+0000] {standard_task_runner.py:83} INFO - Job 1012: Subtask count_row
[2022-11-29T15:52:25.222+0000] {task_command.py:376} INFO - Running <TaskInstance: a_start_dag.count_row manual__2022-11-29T15:52:24.001658+00:00 [running]> on host ab28c0b87467
[2022-11-29T15:52:25.309+0000] {taskinstance.py:1592} INFO - Exporting the following env vars:
AIRFLOW_CTX_DAG_OWNER=***
AIRFLOW_CTX_DAG_ID=a_start_dag
AIRFLOW_CTX_TASK_ID=count_row
AIRFLOW_CTX_EXECUTION_DATE=2022-11-29T15:52:24.001658+00:00
AIRFLOW_CTX_TRY_NUMBER=1
AIRFLOW_CTX_DAG_RUN_ID=manual__2022-11-29T15:52:24.001658+00:00
[2022-11-29T15:52:26.536+0000] {taskinstance.py:1851} ERROR - Task failed with exception
Traceback (most recent call last):
  File "/home/airflow/.local/lib/python3.7/site-packages/airflow/operators/python.py", line 175, in execute
    return_value = self.execute_callable()
  File "/home/airflow/.local/lib/python3.7/site-packages/airflow/operators/python.py", line 193, in execute_callable
    return self.python_callable(*self.op_args, **self.op_kwargs)
  File "/opt/airflow/dags/start_dag.py", line 11, in count_r
    row_sum = r.text.count('\n')-1
  File "/home/airflow/.local/lib/python3.7/site-packages/pandas/core/generic.py", line 5487, in __getattr__
    return object.__getattribute__(self, name)
AttributeError: 'DataFrame' object has no attribute 'text'
[2022-11-29T15:52:26.557+0000] {taskinstance.py:1406} INFO - Marking task as FAILED. dag_id=a_start_dag, task_id=count_row, execution_date=20221129T155224, start_date=20221129T155225, end_date=20221129T155226
[2022-11-29T15:52:26.582+0000] {standard_task_runner.py:105} ERROR - Failed to execute job 1012 for task count_row ('DataFrame' object has no attribute 'text'; 21980)
[2022-11-29T15:52:26.607+0000] {local_task_job.py:159} INFO - Task exited with return code 1
[2022-11-29T15:52:26.673+0000] {taskinstance.py:2623} INFO - 0 downstream tasks scheduled from follow-on schedule check
