[2022-11-30T09:31:49.150+0000] {taskinstance.py:1165} INFO - Dependencies all met for <TaskInstance: a_start_dag.count manual__2022-11-30T09:31:45.465804+00:00 [queued]>
[2022-11-30T09:31:49.162+0000] {taskinstance.py:1165} INFO - Dependencies all met for <TaskInstance: a_start_dag.count manual__2022-11-30T09:31:45.465804+00:00 [queued]>
[2022-11-30T09:31:49.162+0000] {taskinstance.py:1362} INFO - 
--------------------------------------------------------------------------------
[2022-11-30T09:31:49.162+0000] {taskinstance.py:1363} INFO - Starting attempt 1 of 1
[2022-11-30T09:31:49.162+0000] {taskinstance.py:1364} INFO - 
--------------------------------------------------------------------------------
[2022-11-30T09:31:49.177+0000] {taskinstance.py:1383} INFO - Executing <Task(PythonOperator): count> on 2022-11-30 09:31:45.465804+00:00
[2022-11-30T09:31:49.186+0000] {standard_task_runner.py:55} INFO - Started process 3099 to run task
[2022-11-30T09:31:49.190+0000] {standard_task_runner.py:82} INFO - Running: ['***', 'tasks', 'run', 'a_start_dag', 'count', 'manual__2022-11-30T09:31:45.465804+00:00', '--job-id', '1038', '--raw', '--subdir', 'DAGS_FOLDER/start_dag.py', '--cfg-path', '/tmp/tmp9ka4f87t']
[2022-11-30T09:31:49.192+0000] {standard_task_runner.py:83} INFO - Job 1038: Subtask count
[2022-11-30T09:31:49.261+0000] {task_command.py:376} INFO - Running <TaskInstance: a_start_dag.count manual__2022-11-30T09:31:45.465804+00:00 [running]> on host ab28c0b87467
[2022-11-30T09:31:49.340+0000] {taskinstance.py:1592} INFO - Exporting the following env vars:
AIRFLOW_CTX_DAG_OWNER=***
AIRFLOW_CTX_DAG_ID=a_start_dag
AIRFLOW_CTX_TASK_ID=count
AIRFLOW_CTX_EXECUTION_DATE=2022-11-30T09:31:45.465804+00:00
AIRFLOW_CTX_TRY_NUMBER=1
AIRFLOW_CTX_DAG_RUN_ID=manual__2022-11-30T09:31:45.465804+00:00
[2022-11-30T09:31:49.341+0000] {taskinstance.py:1851} ERROR - Task failed with exception
Traceback (most recent call last):
  File "/home/airflow/.local/lib/python3.7/site-packages/airflow/operators/python.py", line 175, in execute
    return_value = self.execute_callable()
  File "/home/airflow/.local/lib/python3.7/site-packages/airflow/operators/python.py", line 193, in execute_callable
    return self.python_callable(*self.op_args, **self.op_kwargs)
  File "/opt/airflow/dags/start_dag.py", line 13, in count_r
    json_table = kwargs['json_table']
KeyError: 'json_table'
[2022-11-30T09:31:49.349+0000] {taskinstance.py:1406} INFO - Marking task as FAILED. dag_id=a_start_dag, task_id=count, execution_date=20221130T093145, start_date=20221130T093149, end_date=20221130T093149
[2022-11-30T09:31:49.363+0000] {standard_task_runner.py:105} ERROR - Failed to execute job 1038 for task count ('json_table'; 3099)
[2022-11-30T09:31:49.400+0000] {local_task_job.py:159} INFO - Task exited with return code 1
[2022-11-30T09:31:49.419+0000] {taskinstance.py:2623} INFO - 0 downstream tasks scheduled from follow-on schedule check
