[2022-11-29T13:07:17.722+0000] {taskinstance.py:1165} INFO - Dependencies all met for <TaskInstance: a_start_dag.count_row manual__2022-11-29T13:07:16.885475+00:00 [queued]>
[2022-11-29T13:07:17.733+0000] {taskinstance.py:1165} INFO - Dependencies all met for <TaskInstance: a_start_dag.count_row manual__2022-11-29T13:07:16.885475+00:00 [queued]>
[2022-11-29T13:07:17.733+0000] {taskinstance.py:1362} INFO - 
--------------------------------------------------------------------------------
[2022-11-29T13:07:17.733+0000] {taskinstance.py:1363} INFO - Starting attempt 1 of 1
[2022-11-29T13:07:17.733+0000] {taskinstance.py:1364} INFO - 
--------------------------------------------------------------------------------
[2022-11-29T13:07:17.751+0000] {taskinstance.py:1383} INFO - Executing <Task(PythonOperator): count_row> on 2022-11-29 13:07:16.885475+00:00
[2022-11-29T13:07:17.758+0000] {standard_task_runner.py:55} INFO - Started process 14738 to run task
[2022-11-29T13:07:17.762+0000] {standard_task_runner.py:82} INFO - Running: ['***', 'tasks', 'run', 'a_start_dag', 'count_row', 'manual__2022-11-29T13:07:16.885475+00:00', '--job-id', '997', '--raw', '--subdir', 'DAGS_FOLDER/start_dag.py', '--cfg-path', '/tmp/tmpxm5dmz42']
[2022-11-29T13:07:17.762+0000] {standard_task_runner.py:83} INFO - Job 997: Subtask count_row
[2022-11-29T13:07:17.826+0000] {task_command.py:376} INFO - Running <TaskInstance: a_start_dag.count_row manual__2022-11-29T13:07:16.885475+00:00 [running]> on host ab28c0b87467
[2022-11-29T13:07:17.904+0000] {taskinstance.py:1592} INFO - Exporting the following env vars:
AIRFLOW_CTX_DAG_OWNER=***
AIRFLOW_CTX_DAG_ID=a_start_dag
AIRFLOW_CTX_TASK_ID=count_row
AIRFLOW_CTX_EXECUTION_DATE=2022-11-29T13:07:16.885475+00:00
AIRFLOW_CTX_TRY_NUMBER=1
AIRFLOW_CTX_DAG_RUN_ID=manual__2022-11-29T13:07:16.885475+00:00
[2022-11-29T13:07:19.024+0000] {logging_mixin.py:137} INFO - Количество строк исключая заголовок = 10000
[2022-11-29T13:07:19.024+0000] {taskinstance.py:1851} ERROR - Task failed with exception
Traceback (most recent call last):
  File "/home/airflow/.local/lib/python3.7/site-packages/airflow/operators/python.py", line 175, in execute
    return_value = self.execute_callable()
  File "/home/airflow/.local/lib/python3.7/site-packages/airflow/operators/python.py", line 193, in execute_callable
    return self.python_callable(*self.op_args, **self.op_kwargs)
  File "/opt/airflow/dags/start_dag.py", line 13, in count_r
    xcom.push(row_sum)
NameError: name 'xcom' is not defined
[2022-11-29T13:07:19.032+0000] {taskinstance.py:1406} INFO - Marking task as FAILED. dag_id=a_start_dag, task_id=count_row, execution_date=20221129T130716, start_date=20221129T130717, end_date=20221129T130719
[2022-11-29T13:07:19.048+0000] {standard_task_runner.py:105} ERROR - Failed to execute job 997 for task count_row (name 'xcom' is not defined; 14738)
[2022-11-29T13:07:19.065+0000] {local_task_job.py:159} INFO - Task exited with return code 1
[2022-11-29T13:07:19.082+0000] {taskinstance.py:2623} INFO - 0 downstream tasks scheduled from follow-on schedule check
