[2022-11-29T13:26:12.405+0000] {taskinstance.py:1165} INFO - Dependencies all met for <TaskInstance: a_start_dag.count_row manual__2022-11-29T13:26:11.554125+00:00 [queued]>
[2022-11-29T13:26:12.416+0000] {taskinstance.py:1165} INFO - Dependencies all met for <TaskInstance: a_start_dag.count_row manual__2022-11-29T13:26:11.554125+00:00 [queued]>
[2022-11-29T13:26:12.416+0000] {taskinstance.py:1362} INFO - 
--------------------------------------------------------------------------------
[2022-11-29T13:26:12.416+0000] {taskinstance.py:1363} INFO - Starting attempt 1 of 1
[2022-11-29T13:26:12.416+0000] {taskinstance.py:1364} INFO - 
--------------------------------------------------------------------------------
[2022-11-29T13:26:12.441+0000] {taskinstance.py:1383} INFO - Executing <Task(PythonOperator): count_row> on 2022-11-29 13:26:11.554125+00:00
[2022-11-29T13:26:12.449+0000] {standard_task_runner.py:55} INFO - Started process 15572 to run task
[2022-11-29T13:26:12.453+0000] {standard_task_runner.py:82} INFO - Running: ['***', 'tasks', 'run', 'a_start_dag', 'count_row', 'manual__2022-11-29T13:26:11.554125+00:00', '--job-id', '1003', '--raw', '--subdir', 'DAGS_FOLDER/start_dag.py', '--cfg-path', '/tmp/tmp9di1w5tn']
[2022-11-29T13:26:12.453+0000] {standard_task_runner.py:83} INFO - Job 1003: Subtask count_row
[2022-11-29T13:26:12.619+0000] {task_command.py:376} INFO - Running <TaskInstance: a_start_dag.count_row manual__2022-11-29T13:26:11.554125+00:00 [running]> on host ab28c0b87467
[2022-11-29T13:26:12.781+0000] {taskinstance.py:1592} INFO - Exporting the following env vars:
AIRFLOW_CTX_DAG_OWNER=***
AIRFLOW_CTX_DAG_ID=a_start_dag
AIRFLOW_CTX_TASK_ID=count_row
AIRFLOW_CTX_EXECUTION_DATE=2022-11-29T13:26:11.554125+00:00
AIRFLOW_CTX_TRY_NUMBER=1
AIRFLOW_CTX_DAG_RUN_ID=manual__2022-11-29T13:26:11.554125+00:00
[2022-11-29T13:26:13.909+0000] {logging_mixin.py:137} INFO - Количество строк исключая заголовок = 10000
[2022-11-29T13:26:13.909+0000] {taskinstance.py:1851} ERROR - Task failed with exception
Traceback (most recent call last):
  File "/home/airflow/.local/lib/python3.7/site-packages/airflow/operators/python.py", line 175, in execute
    return_value = self.execute_callable()
  File "/home/airflow/.local/lib/python3.7/site-packages/airflow/operators/python.py", line 193, in execute_callable
    return self.python_callable(*self.op_args, **self.op_kwargs)
  File "/opt/airflow/dags/start_dag.py", line 13, in count_r
    row_sum.xcom.push(answer = row_sum)
AttributeError: 'int' object has no attribute 'xcom'
[2022-11-29T13:26:13.918+0000] {taskinstance.py:1406} INFO - Marking task as FAILED. dag_id=a_start_dag, task_id=count_row, execution_date=20221129T132611, start_date=20221129T132612, end_date=20221129T132613
[2022-11-29T13:26:13.938+0000] {standard_task_runner.py:105} ERROR - Failed to execute job 1003 for task count_row ('int' object has no attribute 'xcom'; 15572)
[2022-11-29T13:26:13.984+0000] {local_task_job.py:159} INFO - Task exited with return code 1
[2022-11-29T13:26:14.004+0000] {taskinstance.py:2623} INFO - 0 downstream tasks scheduled from follow-on schedule check
